Workbook

Sheet Experiment
A1: NaCl 0.01mol/L | C1: 20180907/180907145103.csv
A2: Frequency[Hz] | B2: Z[ohm] | C2: PHASE[deg] | D2: Rs[ohm] | E2: X[ohm]
A3: 1000000 | B3: 929.421 | C3: -2.022 | D3: 928.843 | E3: -32.7901
A4: 1000000 | B4: 929.226 | C4: -1.997 | D4: 928.662 | E4: -32.3745
A5: 1100000 | B5: 926.125 | C5: -2.228 | D5: 925.425 | E5: -36.0005
A6: 1100000 | B6: 925.98 | C6: -2.17 | D6: 925.316 | E6: -35.0619
A7: 1200000 | B7: 923.724 | C7: -2.373 | D7: 922.932 | E7: -38.2436
A8: 1200000 | B8: 925.14 | C8: -2.385 | D8: 924.339 | E8: -38.4927
A9: 1300000 | B9: 923.385 | C9: -2.563 | D9: 922.462 | E9: -41.2864
A10: 1300000 | B10: 922.457 | C10: -2.582 | D10: 921.52 | E10: -41.5596
A11: 1400000 | B11: 922.355 | C11: -2.747 | D11: 921.295 | E11: -44.1997
A12: 1400000 | B12: 923.148 | C12: -2.73 | D12: 922.1 | E12: -43.9694
A13: 1500000 | B13: 923.417 | C13: -2.97 | D13: 922.177 | E13: -47.8399
A14: 1600000 | B14: 923.664 | C14: -3.156 | D14: 922.263 | E14: -50.8467
... A202: 3000000000 | B202: 107.679 | C202: -85.487 | D202: 8.47314 | E202: -107.345

Sheet Reflection
A1: =Experiment!#REF! -> #REF! | B1: unit | C1: 0+1i | I1: =Experiment!#REF! -> #REF! | J1: unit | K1: 0+1i | Q1: =Experiment!A1 -> NaCl 0.01mol/L | R1: unit | S1: 0+1i | Y1: =Experiment!#REF! -> #REF! | Z1: unit | AA1: 0+1i
A2: Frequency[Hz] | B2: U | C2: V | D2: U+iV | E2: RC | F2: RL | I2: Frequency[Hz] | J2: U | K2: V | L2: U+iV | M2: RC | N2: RL | Q2: Frequency[Hz] | R2: U | S2: V | T2: U+iV | U2: RC | V2: RL | Y2: Frequency[Hz] | Z2: U | AA2: V | AB2: U+iV | AC2: RC | AD2: RL
A3: =Experiment!#REF! -> #REF! | B3: =((Experiment!#REF!+50)*(Experiment!#REF!-50)+(Experiment!#REF!^2))/((Experiment!#REF!+50)^2+(Experiment!#REF!^2)) -> #REF! | C3: =((Experiment!#REF!+50)*Experiment!#REF!-Experiment!#REF!*(Experiment!#REF!-50))/((Experiment!#REF!+50)^2+(Experiment!#REF!^2)) -> #REF! | D3: =IMSUM(B3,IMPRODUCT(C3,$C$1)) -> #REF! | E3: =SQRT(B3^2+C3^2) -> #REF! | F3: =-20*LOG(ABS(E3)) -> #REF! | I3: =Experiment!#REF! -> #REF! | J3: =((Experiment!#REF!+50)*(Experiment!#REF!-50)+(Experiment!#REF!^2))/((Experiment!#REF!+50)^2+(Experiment!#REF!^2)) -> #REF! | K3: =((Experiment!#REF!+50)*Experiment!#REF!-Experiment!#REF!*(Experiment!#REF!-50))/((Experiment!#REF!+50)^2+(Experiment!#REF!^2)) -> #REF! | L3: =IMSUM(J3,IMPRODUCT(K3,$K$1)) -> #REF! | M3: =SQRT(J3^2+K3^2) -> #REF! | N3: =-20*LOG(ABS(M3)) -> #REF! | Q3: =Experiment!A3 -> 1000000 | R3: =((Experiment!D3+50)*(Experiment!D3-50)+(Experiment!E3^2))/((Experiment!D3+50)^2+(Experiment!E3^2)) -> 0.89795308 | S3: =((Experiment!D3+50)*Experiment!E3-Experiment!E3*(Experiment!D3-50))/((Experiment!D3+50)^2+(Experiment!E3^2)) -> -0.0034184528 | T3: =IMSUM(R3,IMPRODUCT(S3,$S$1)) -> 0.8979530848234-0.00341845275834044i | U3: =SQRT(R3^2+S3^2) -> 0.89795959 | V3: =-20*LOG(ABS(U3)) -> 0.93486412 | Y3: =Experiment!#REF! -> #REF! | Z3: =((Experiment!#REF!+50)*(Experiment!#REF!-50)+(Experiment!#REF!^2))/((Experiment!#REF!+50)^2+(Experiment!#REF!^2)) -> #REF! | AA3: =((Experiment!#REF!+50)*Experiment!#REF!-Experiment!#REF!*(Experiment!#REF!-50))/((Experiment!#REF!+50)^2+(Experiment!#REF!^2)) -> #REF! | AB3: =IMSUM(Z3,IMPRODUCT(AA3,$AA$1)) -> #REF! | AC3: =SQRT(Z3^2+AA3^2) -> #REF! | AD3: =-20*LOG(ABS(AC3)) -> #REF!
A4: =Experiment!#REF! -> #REF! | B4: =((Experiment!#REF!+50)*(Experiment!#REF!-50)+(Experiment!#REF!^2))/((Experiment!#REF!+50)^2+(Experiment!#REF!^2)) -> #REF! | C4: =((Experiment!#REF!+50)*Experiment!#REF!-Experiment!#REF!*(Experiment!#REF!-50))/((Experiment!#REF!+50)^2+(Experiment!#REF!^2)) -> #REF! | D4: =IMSUM(B4,IMPRODUCT(C4,$C$1)) -> #REF! | E4: =SQRT(B4^2+C4^2) -> #REF! | F4: =-20*LOG(ABS(E4)) -> #REF! | I4: =Experiment!#REF! -> #REF! | J4: =((Experiment!#REF!+50)*(Experiment!#REF!-50)+(Experiment!#REF!^2))/((Experiment!#REF!+50)^2+(Experiment!#REF!^2)) -> #REF! | K4: =((Experiment!#REF!+50)*Experiment!#REF!-Experiment!#REF!*(Experiment!#REF!-50))/((Experiment!#REF!+50)^2+(Experiment!#REF!^2)) -> #REF! | L4: =IMSUM(J4,IMPRODUCT(K4,$K$1)) -> #REF! | M4: =SQRT(J4^2+K4^2) -> #REF! | N4: =-20*LOG(ABS(M4)) -> #REF! | Q4: =Experiment!A4 -> 1000000 | R4: =((Experiment!D4+50)*(Experiment!D4-50)+(Experiment!E4^2))/((Experiment!D4+50)^2+(Experiment!E4^2)) -> 0.89793137 | S4: =((Experiment!D4+50)*Experiment!E4-Experiment!E4*(Experiment!D4-50))/((Experiment!D4+50)^2+(Experiment!E4^2)) -> -0.0033764679 | T4: =IMSUM(R4,IMPRODUCT(S4,$S$1)) -> 0.897931371055607-0.00337646789980632i | U4: =SQRT(R4^2+S4^2) -> 0.89793772 | V4: =-20*LOG(ABS(U4)) -> 0.9350757 | Y4: =Experiment!#REF! -> #REF! | Z4: =((Experiment!#REF!+50)*(Experiment!#REF!-50)+(Experiment!#REF!^2))/((Experiment!#REF!+50)^2+(Experiment!#REF!^2)) -> #REF! | AA4: =((Experiment!#REF!+50)*Experiment!#REF!-Experiment!#REF!*(Experiment!#REF!-50))/((Experiment!#REF!+50)^2+(Experiment!#REF!^2)) -> #REF! | AB4: =IMSUM(Z4,IMPRODUCT(AA4,$AA$1)) -> #REF! | AC4: =SQRT(Z4^2+AA4^2) -> #REF! | AD4: =-20*LOG(ABS(AC4)) -> #REF!
A5: =Experiment!#REF! -> #REF! | B5: =((Experiment!#REF!+50)*(Experiment!#REF!-50)+(Experiment!#REF!^2))/((Experiment!#REF!+50)^2+(Experiment!#REF!^2)) -> #REF! | C5: =((Experiment!#REF!+50)*Experiment!#REF!-Experiment!#REF!*(Experiment!#REF!-50))/((Experiment!#REF!+50)^2+(Experiment!#REF!^2)) -> #REF! | D5: =IMSUM(B5,IMPRODUCT(C5,$C$1)) -> #REF! | E5: =SQRT(B5^2+C5^2) -> #REF! | F5: =-20*LOG(ABS(E5)) -> #REF! | I5: =Experiment!#REF! -> #REF! | J5: =((Experiment!#REF!+50)*(Experiment!#REF!-50)+(Experiment!#REF!^2))/((Experiment!#REF!+50)^2+(Experiment!#REF!^2)) -> #REF! | K5: =((Experiment!#REF!+50)*Experiment!#REF!-Experiment!#REF!*(Experiment!#REF!-50))/((Experiment!#REF!+50)^2+(Experiment!#REF!^2)) -> #REF! | L5: =IMSUM(J5,IMPRODUCT(K5,$K$1)) -> #REF! | M5: =SQRT(J5^2+K5^2) -> #REF! | N5: =-20*LOG(ABS(M5)) -> #REF! | Q5: =Experiment!A5 -> 1100000 | R5: =((Experiment!D5+50)*(Experiment!D5-50)+(Experiment!E5^2))/((Experiment!D5+50)^2+(Experiment!E5^2)) -> 0.89762004 | S5: =((Experiment!D5+50)*Experiment!E5-Experiment!E5*(Experiment!D5-50))/((Experiment!D5+50)^2+(Experiment!E5^2)) -> -0.0037785884 | T5: =IMSUM(R5,IMPRODUCT(S5,$S$1)) -> 0.897620043645337-0.00377858842939852i | U5: =SQRT(R5^2+S5^2) -> 0.897628 | V5: =-20*LOG(ABS(U5)) -> 0.93807221 | Y5: =Experiment!#REF! -> #REF! | Z5: =((Experiment!#REF!+50)*(Experiment!#REF!-50)+(Experiment!#REF!^2))/((Experiment!#REF!+50)^2+(Experiment!#REF!^2)) -> #REF! | AA5: =((Experiment!#REF!+50)*Experiment!#REF!-Experiment!#REF!*(Experiment!#REF!-50))/((Experiment!#REF!+50)^2+(Experiment!#REF!^2)) -> #REF! | AB5: =IMSUM(Z5,IMPRODUCT(AA5,$AA$1)) -> #REF! | AC5: =SQRT(Z5^2+AA5^2) -> #REF! | AD5: =-20*LOG(ABS(AC5)) -> #REF!
A6: =Experiment!#REF! -> #REF! | B6: =((Experiment!#REF!+50)*(Experiment!#REF!-50)+(Experiment!#REF!^2))/((Experiment!#REF!+50)^2+(Experiment!#REF!^2)) -> #REF! | C6: =((Experiment!#REF!+50)*Experiment!#REF!-Experiment!#REF!*(Experiment!#REF!-50))/((Experiment!#REF!+50)^2+(Experiment!#REF!^2)) -> #REF! | D6: =IMSUM(B6,IMPRODUCT(C6,$C$1)) -> #REF! | E6: =SQRT(B6^2+C6^2) -> #REF! | F6: =-20*LOG(ABS(E6)) -> #REF! | I6: =Experiment!#REF! -> #REF! | J6: =((Experiment!#REF!+50)*(Experiment!#REF!-50)+(Experiment!#REF!^2))/((Experiment!#REF!+50)^2+(Experiment!#REF!^2)) -> #REF! | K6: =((Experiment!#REF!+50)*Experiment!#REF!-Experiment!#REF!*(Experiment!#REF!-50))/((Experiment!#REF!+50)^2+(Experiment!#REF!^2)) -> #REF! | L6: =IMSUM(J6,IMPRODUCT(K6,$K$1)) -> #REF! | M6: =SQRT(J6^2+K6^2) -> #REF! | N6: =-20*LOG(ABS(M6)) -> #REF! | Q6: =Experiment!A6 -> 1100000 | R6: =((Experiment!D6+50)*(Experiment!D6-50)+(Experiment!E6^2))/((Experiment!D6+50)^2+(Experiment!E6^2)) -> 0.89760146 | S6: =((Experiment!D6+50)*Experiment!E6-Experiment!E6*(Experiment!D6-50))/((Experiment!D6+50)^2+(Experiment!E6^2)) -> -0.0036811529 | T6: =IMSUM(R6,IMPRODUCT(S6,$S$1)) -> 0.89760146271891-0.00368115285127677i | U6: =SQRT(R6^2+S6^2) -> 0.89760901 | V6: =-20*LOG(ABS(U6)) -> 0.93825592 | Y6: =Experiment!#REF! -> #REF! | Z6: =((Experiment!#REF!+50)*(Experiment!#REF!-50)+(Experiment!#REF!^2))/((Experiment!#REF!+50)^2+(Experiment!#REF!^2)) -> #REF! | AA6: =((Experiment!#REF!+50)*Experiment!#REF!-Experiment!#REF!*(Experiment!#REF!-50))/((Experiment!#REF!+50)^2+(Experiment!#REF!^2)) -> #REF! | AB6: =IMSUM(Z6,IMPRODUCT(AA6,$AA$1)) -> #REF! | AC6: =SQRT(Z6^2+AA6^2) -> #REF! | AD6: =-20*LOG(ABS(AC6)) -> #REF!
A7: =Experiment!#REF! -> #REF! | B7: =((Experiment!#REF!+50)*(Experiment!#REF!-50)+(Experiment!#REF!^2))/((Experiment!#REF!+50)^2+(Experiment!#REF!^2)) -> #REF! | C7: =((Experiment!#REF!+50)*Experiment!#REF!-Experiment!#REF!*(Experiment!#REF!-50))/((Experiment!#REF!+50)^2+(Experiment!#REF!^2)) -> #REF! | D7: =IMSUM(B7,IMPRODUCT(C7,$C$1)) -> #REF! | E7: =SQRT(B7^2+C7^2) -> #REF! | F7: =-20*LOG(ABS(E7)) -> #REF! | I7: =Experiment!#REF! -> #REF! | J7: =((Experiment!#REF!+50)*(Experiment!#REF!-50)+(Experiment!#REF!^2))/((Experiment!#REF!+50)^2+(Experiment!#REF!^2)) -> #REF! | K7: =((Experiment!#REF!+50)*Experiment!#REF!-Experiment!#REF!*(Experiment!#REF!-50))/((Experiment!#REF!+50)^2+(Experiment!#REF!^2)) -> #REF! | L7: =IMSUM(J7,IMPRODUCT(K7,$K$1)) -> #REF! | M7: =SQRT(J7^2+K7^2) -> #REF! | N7: =-20*LOG(ABS(M7)) -> #REF! | Q7: =Experiment!A7 -> 1200000 | R7: =((Experiment!D7+50)*(Experiment!D7-50)+(Experiment!E7^2))/((Experiment!D7+50)^2+(Experiment!E7^2)) -> 0.89737646 | S7: =((Experiment!D7+50)*Experiment!E7-Experiment!E7*(Experiment!D7-50))/((Experiment!D7+50)^2+(Experiment!E7^2)) -> -0.0040338829 | T7: =IMSUM(R7,IMPRODUCT(S7,$S$1)) -> 0.897376456118491-0.00403388290526663i | U7: =SQRT(R7^2+S7^2) -> 0.89738552 | V7: =-20*LOG(ABS(U7)) -> 0.94041882 | Y7: =Experiment!#REF! -> #REF! | Z7: =((Experiment!#REF!+50)*(Experiment!#REF!-50)+(Experiment!#REF!^2))/((Experiment!#REF!+50)^2+(Experiment!#REF!^2)) -> #REF! | AA7: =((Experiment!#REF!+50)*Experiment!#REF!-Experiment!#REF!*(Experiment!#REF!-50))/((Experiment!#REF!+50)^2+(Experiment!#REF!^2)) -> #REF! | AB7: =IMSUM(Z7,IMPRODUCT(AA7,$AA$1)) -> #REF! | AC7: =SQRT(Z7^2+AA7^2) -> #REF! | AD7: =-20*LOG(ABS(AC7)) -> #REF!
A8: =Experiment!#REF! -> #REF! | B8: =((Experiment!#REF!+50)*(Experiment!#REF!-50)+(Experiment!#REF!^2))/((Experiment!#REF!+50)^2+(Experiment!#REF!^2)) -> #REF! | C8: =((Experiment!#REF!+50)*Experiment!#REF!-Experiment!#REF!*(Experiment!#REF!-50))/((Experiment!#REF!+50)^2+(Experiment!#REF!^2)) -> #REF! | D8: =IMSUM(B8,IMPRODUCT(C8,$C$1)) -> #REF! | E8: =SQRT(B8^2+C8^2) -> #REF! | F8: =-20*LOG(ABS(E8)) -> #REF! | I8: =Experiment!#REF! -> #REF! | J8: =((Experiment!#REF!+50)*(Experiment!#REF!-50)+(Experiment!#REF!^2))/((Experiment!#REF!+50)^2+(Experiment!#REF!^2)) -> #REF! | K8: =((Experiment!#REF!+50)*Experiment!#REF!-Experiment!#REF!*(Experiment!#REF!-50))/((Experiment!#REF!+50)^2+(Experiment!#REF!^2)) -> #REF! | L8: =IMSUM(J8,IMPRODUCT(K8,$K$1)) -> #REF! | M8: =SQRT(J8^2+K8^2) -> #REF! | N8: =-20*LOG(ABS(M8)) -> #REF! | Q8: =Experiment!A8 -> 1200000 | R8: =((Experiment!D8+50)*(Experiment!D8-50)+(Experiment!E8^2))/((Experiment!D8+50)^2+(Experiment!E8^2)) -> 0.89752625 | S8: =((Experiment!D8+50)*Experiment!E8-Experiment!E8*(Experiment!D8-50))/((Experiment!D8+50)^2+(Experiment!E8^2)) -> -0.0040483765 | T8: =IMSUM(R8,IMPRODUCT(S8,$S$1)) -> 0.897526254151713-0.00404837654739711i | U8: =SQRT(R8^2+S8^2) -> 0.89753538 | V8: =-20*LOG(ABS(U8)) -> 0.93896842 | Y8: =Experiment!#REF! -> #REF! | Z8: =((Experiment!#REF!+50)*(Experiment!#REF!-50)+(Experiment!#REF!^2))/((Experiment!#REF!+50)^2+(Experiment!#REF!^2)) -> #REF! | AA8: =((Experiment!#REF!+50)*Experiment!#REF!-Experiment!#REF!*(Experiment!#REF!-50))/((Experiment!#REF!+50)^2+(Experiment!#REF!^2)) -> #REF! | AB8: =IMSUM(Z8,IMPRODUCT(AA8,$AA$1)) -> #REF! | AC8: =SQRT(Z8^2+AA8^2) -> #REF! | AD8: =-20*LOG(ABS(AC8)) -> #REF!
A9: =Experiment!#REF! -> #REF! | B9: =((Experiment!#REF!+50)*(Experiment!#REF!-50)+(Experiment!#REF!^2))/((Experiment!#REF!+50)^2+(Experiment!#REF!^2)) -> #REF! | C9: =((Experiment!#REF!+50)*Experiment!#REF!-Experiment!#REF!*(Experiment!#REF!-50))/((Experiment!#REF!+50)^2+(Experiment!#REF!^2)) -> #REF! | D9: =IMSUM(B9,IMPRODUCT(C9,$C$1)) -> #REF! | E9: =SQRT(B9^2+C9^2) -> #REF! | F9: =-20*LOG(ABS(E9)) -> #REF! | I9: =Experiment!#REF! -> #REF! | J9: =((Experiment!#REF!+50)*(Experiment!#REF!-50)+(Experiment!#REF!^2))/((Experiment!#REF!+50)^2+(Experiment!#REF!^2)) -> #REF! | K9: =((Experiment!#REF!+50)*Experiment!#REF!-Experiment!#REF!*(Experiment!#REF!-50))/((Experiment!#REF!+50)^2+(Experiment!#REF!^2)) -> #REF! | L9: =IMSUM(J9,IMPRODUCT(K9,$K$1)) -> #REF! | M9: =SQRT(J9^2+K9^2) -> #REF! | N9: =-20*LOG(ABS(M9)) -> #REF! | Q9: =Experiment!A9 -> 1300000 | R9: =((Experiment!D9+50)*(Experiment!D9-50)+(Experiment!E9^2))/((Experiment!D9+50)^2+(Experiment!E9^2)) -> 0.89735324 | S9: =((Experiment!D9+50)*Experiment!E9-Experiment!E9*(Experiment!D9-50))/((Experiment!D9+50)^2+(Experiment!E9^2)) -> -0.0043579238 | T9: =IMSUM(R9,IMPRODUCT(S9,$S$1)) -> 0.89735323641142-0.00435792384712572i | U9: =SQRT(R9^2+S9^2) -> 0.89736382 | V9: =-20*LOG(ABS(U9)) -> 0.9406289 | Y9: =Experiment!#REF! -> #REF! | Z9: =((Experiment!#REF!+50)*(Experiment!#REF!-50)+(Experiment!#REF!^2))/((Experiment!#REF!+50)^2+(Experiment!#REF!^2)) -> #REF! | AA9: =((Experiment!#REF!+50)*Experiment!#REF!-Experiment!#REF!*(Experiment!#REF!-50))/((Experiment!#REF!+50)^2+(Experiment!#REF!^2)) -> #REF! | AB9: =IMSUM(Z9,IMPRODUCT(AA9,$AA$1)) -> #REF! | AC9: =SQRT(Z9^2+AA9^2) -> #REF! | AD9: =-20*LOG(ABS(AC9)) -> #REF!
A10: =Experiment!#REF! -> #REF! | B10: =((Experiment!#REF!+50)*(Experiment!#REF!-50)+(Experiment!#REF!^2))/((Experiment!#REF!+50)^2+(Experiment!#REF!^2)) -> #REF! | C10: =((Experiment!#REF!+50)*Experiment!#REF!-Experiment!#REF!*(Experiment!#REF!-50))/((Experiment!#REF!+50)^2+(Experiment!#REF!^2)) -> #REF! | D10: =IMSUM(B10,IMPRODUCT(C10,$C$1)) -> #REF! | E10: =SQRT(B10^2+C10^2) -> #REF! | F10: =-20*LOG(ABS(E10)) -> #REF! | I10: =Experiment!#REF! -> #REF! | J10: =((Experiment!#REF!+50)*(Experiment!#REF!-50)+(Experiment!#REF!^2))/((Experiment!#REF!+50)^2+(Experiment!#REF!^2)) -> #REF! | K10: =((Experiment!#REF!+50)*Experiment!#REF!-Experiment!#REF!*(Experiment!#REF!-50))/((Experiment!#REF!+50)^2+(Experiment!#REF!^2)) -> #REF! | L10: =IMSUM(J10,IMPRODUCT(K10,$K$1)) -> #REF! | M10: =SQRT(J10^2+K10^2) -> #REF! | N10: =-20*LOG(ABS(M10)) -> #REF! | Q10: =Experiment!A10 -> 1300000 | R10: =((Experiment!D10+50)*(Experiment!D10-50)+(Experiment!E10^2))/((Experiment!D10+50)^2+(Experiment!E10^2)) -> 0.89725653 | S10: =((Experiment!D10+50)*Experiment!E10-Experiment!E10*(Experiment!D10-50))/((Experiment!D10+50)^2+(Experiment!E10^2)) -> -0.0043951516 | T10: =IMSUM(R10,IMPRODUCT(S10,$S$1)) -> 0.897256526619439-0.00439515157310889i | U10: =SQRT(R10^2+S10^2) -> 0.89726729 | V10: =-20*LOG(ABS(U10)) -> 0.94156327 | Y10: =Experiment!#REF! -> #REF! | Z10: =((Experiment!#REF!+50)*(Experiment!#REF!-50)+(Experiment!#REF!^2))/((Experiment!#REF!+50)^2+(Experiment!#REF!^2)) -> #REF! | AA10: =((Experiment!#REF!+50)*Experiment!#REF!-Experiment!#REF!*(Experiment!#REF!-50))/((Experiment!#REF!+50)^2+(Experiment!#REF!^2)) -> #REF! | AB10: =IMSUM(Z10,IMPRODUCT(AA10,$AA$1)) -> #REF! | AC10: =SQRT(Z10^2+AA10^2) -> #REF! | AD10: =-20*LOG(ABS(AC10)) -> #REF!
A11: =Experiment!#REF! -> #REF! | B11: =((Experiment!#REF!+50)*(Experiment!#REF!-50)+(Experiment!#REF!^2))/((Experiment!#REF!+50)^2+(Experiment!#REF!^2)) -> #REF! | C11: =((Experiment!#REF!+50)*Experiment!#REF!-Experiment!#REF!*(Experiment!#REF!-50))/((Experiment!#REF!+50)^2+(Experiment!#REF!^2)) -> #REF! | D11: =IMSUM(B11,IMPRODUCT(C11,$C$1)) -> #REF! | E11: =SQRT(B11^2+C11^2) -> #REF! | F11: =-20*LOG(ABS(E11)) -> #REF! | I11: =Experiment!#REF! -> #REF! | J11: =((Experiment!#REF!+50)*(Experiment!#REF!-50)+(Experiment!#REF!^2))/((Experiment!#REF!+50)^2+(Experiment!#REF!^2)) -> #REF! | K11: =((Experiment!#REF!+50)*Experiment!#REF!-Experiment!#REF!*(Experiment!#REF!-50))/((Experiment!#REF!+50)^2+(Experiment!#REF!^2)) -> #REF! | L11: =IMSUM(J11,IMPRODUCT(K11,$K$1)) -> #REF! | M11: =SQRT(J11^2+K11^2) -> #REF! | N11: =-20*LOG(ABS(M11)) -> #REF! | Q11: =Experiment!A11 -> 1400000 | R11: =((Experiment!D11+50)*(Experiment!D11-50)+(Experiment!E11^2))/((Experiment!D11+50)^2+(Experiment!E11^2)) -> 0.89725743 | S11: =((Experiment!D11+50)*Experiment!E11-Experiment!E11*(Experiment!D11-50))/((Experiment!D11+50)^2+(Experiment!E11^2)) -> -0.0046753983 | T11: =IMSUM(R11,IMPRODUCT(S11,$S$1)) -> 0.897257425602981-0.00467539827300247i | U11: =SQRT(R11^2+S11^2) -> 0.89726961 | V11: =-20*LOG(ABS(U11)) -> 0.94154086 | Y11: =Experiment!#REF! -> #REF! | Z11: =((Experiment!#REF!+50)*(Experiment!#REF!-50)+(Experiment!#REF!^2))/((Experiment!#REF!+50)^2+(Experiment!#REF!^2)) -> #REF! | AA11: =((Experiment!#REF!+50)*Experiment!#REF!-Experiment!#REF!*(Experiment!#REF!-50))/((Experiment!#REF!+50)^2+(Experiment!#REF!^2)) -> #REF! | AB11: =IMSUM(Z11,IMPRODUCT(AA11,$AA$1)) -> #REF! | AC11: =SQRT(Z11^2+AA11^2) -> #REF! | AD11: =-20*LOG(ABS(AC11)) -> #REF!
A12: =Experiment!#REF! -> #REF! | B12: =((Experiment!#REF!+50)*(Experiment!#REF!-50)+(Experiment!#REF!^2))/((Experiment!#REF!+50)^2+(Experiment!#REF!^2)) -> #REF! | C12: =((Experiment!#REF!+50)*Experiment!#REF!-Experiment!#REF!*(Experiment!#REF!-50))/((Experiment!#REF!+50)^2+(Experiment!#REF!^2)) -> #REF! | D12: =IMSUM(B12,IMPRODUCT(C12,$C$1)) -> #REF! | E12: =SQRT(B12^2+C12^2) -> #REF! | F12: =-20*LOG(ABS(E12)) -> #REF! | I12: =Experiment!#REF! -> #REF! | J12: =((Experiment!#REF!+50)*(Experiment!#REF!-50)+(Experiment!#REF!^2))/((Experiment!#REF!+50)^2+(Experiment!#REF!^2)) -> #REF! | K12: =((Experiment!#REF!+50)*Experiment!#REF!-Experiment!#REF!*(Experiment!#REF!-50))/((Experiment!#REF!+50)^2+(Experiment!#REF!^2)) -> #REF! | L12: =IMSUM(J12,IMPRODUCT(K12,$K$1)) -> #REF! | M12: =SQRT(J12^2+K12^2) -> #REF! | N12: =-20*LOG(ABS(M12)) -> #REF! | Q12: =Experiment!A12 -> 1400000 | R12: =((Experiment!D12+50)*(Experiment!D12-50)+(Experiment!E12^2))/((Experiment!D12+50)^2+(Experiment!E12^2)) -> 0.89733995 | S12: =((Experiment!D12+50)*Experiment!E12-Experiment!E12*(Experiment!D12-50))/((Experiment!D12+50)^2+(Experiment!E12^2)) -> -0.0046434529 | T12: =IMSUM(R12,IMPRODUCT(S12,$S$1)) -> 0.897339954572195-0.00464345293841513i | U12: =SQRT(R12^2+S12^2) -> 0.89735197 | V12: =-20*LOG(ABS(U12)) -> 0.9407436 | Y12: =Experiment!#REF! -> #REF! | Z12: =((Experiment!#REF!+50)*(Experiment!#REF!-50)+(Experiment!#REF!^2))/((Experiment!#REF!+50)^2+(Experiment!#REF!^2)) -> #REF! | AA12: =((Experiment!#REF!+50)*Experiment!#REF!-Experiment!#REF!*(Experiment!#REF!-50))/((Experiment!#REF!+50)^2+(Experiment!#REF!^2)) -> #REF! | AB12: =IMSUM(Z12,IMPRODUCT(AA12,$AA$1)) -> #REF! | AC12: =SQRT(Z12^2+AA12^2) -> #REF! | AD12: =-20*LOG(ABS(AC12)) -> #REF!
A13: =Experiment!#REF! -> #REF! | B13: =((Experiment!#REF!+50)*(Experiment!#REF!-50)+(Experiment!#REF!^2))/((Experiment!#REF!+50)^2+(Experiment!#REF!^2)) -> #REF! | C13: =((Experiment!#REF!+50)*Experiment!#REF!-Experiment!#REF!*(Experiment!#REF!-50))/((Experiment!#REF!+50)^2+(Experiment!#REF!^2)) -> #REF! | D13: =IMSUM(B13,IMPRODUCT(C13,$C$1)) -> #REF! | E13: =SQRT(B13^2+C13^2) -> #REF! | F13: =-20*LOG(ABS(E13)) -> #REF! | I13: =Experiment!#REF! -> #REF! | J13: =((Experiment!#REF!+50)*(Experiment!#REF!-50)+(Experiment!#REF!^2))/((Experiment!#REF!+50)^2+(Experiment!#REF!^2)) -> #REF! | K13: =((Experiment!#REF!+50)*Experiment!#REF!-Experiment!#REF!*(Experiment!#REF!-50))/((Experiment!#REF!+50)^2+(Experiment!#REF!^2)) -> #REF! | L13: =IMSUM(J13,IMPRODUCT(K13,$K$1)) -> #REF! | M13: =SQRT(J13^2+K13^2) -> #REF! | N13: =-20*LOG(ABS(M13)) -> #REF! | Q13: =Experiment!A13 -> 1500000 | R13: =((Experiment!D13+50)*(Experiment!D13-50)+(Experiment!E13^2))/((Experiment!D13+50)^2+(Experiment!E13^2)) -> 0.89738655 | S13: =((Experiment!D13+50)*Experiment!E13-Experiment!E13*(Experiment!D13-50))/((Experiment!D13+50)^2+(Experiment!E13^2)) -> -0.0050495095 | T13: =IMSUM(R13,IMPRODUCT(S13,$S$1)) -> 0.89738655412455-0.00504950949193092i | U13: =SQRT(R13^2+S13^2) -> 0.89740076 | V13: =-20*LOG(ABS(U13)) -> 0.94027133 | Y13: =Experiment!#REF! -> #REF! | Z13: =((Experiment!#REF!+50)*(Experiment!#REF!-50)+(Experiment!#REF!^2))/((Experiment!#REF!+50)^2+(Experiment!#REF!^2)) -> #REF! | AA13: =((Experiment!#REF!+50)*Experiment!#REF!-Experiment!#REF!*(Experiment!#REF!-50))/((Experiment!#REF!+50)^2+(Experiment!#REF!^2)) -> #REF! | AB13: =IMSUM(Z13,IMPRODUCT(AA13,$AA$1)) -> #REF! | AC13: =SQRT(Z13^2+AA13^2) -> #REF! | AD13: =-20*LOG(ABS(AC13)) -> #REF!
A14: =Experiment!#REF! -> #REF! | B14: =((Experiment!#REF!+50)*(Experiment!#REF!-50)+(Experiment!#REF!^2))/((Experiment!#REF!+50)^2+(Experiment!#REF!^2)) -> #REF! | C14: =((Experiment!#REF!+50)*Experiment!#REF!-Experiment!#REF!*(Experiment!#REF!-50))/((Experiment!#REF!+50)^2+(Experiment!#REF!^2)) -> #REF! | D14: =IMSUM(B14,IMPRODUCT(C14,$C$1)) -> #REF! | E14: =SQRT(B14^2+C14^2) -> #REF! | F14: =-20*LOG(ABS(E14)) -> #REF! | I14: =Experiment!#REF! -> #REF! | J14: =((Experiment!#REF!+50)*(Experiment!#REF!-50)+(Experiment!#REF!^2))/((Experiment!#REF!+50)^2+(Experiment!#REF!^2)) -> #REF! | K14: =((Experiment!#REF!+50)*Experiment!#REF!-Experiment!#REF!*(Experiment!#REF!-50))/((Experiment!#REF!+50)^2+(Experiment!#REF!^2)) -> #REF! | L14: =IMSUM(J14,IMPRODUCT(K14,$K$1)) -> #REF! | M14: =SQRT(J14^2+K14^2) -> #REF! | N14: =-20*LOG(ABS(M14)) -> #REF! | Q14: =Experiment!A14 -> 1600000 | R14: =((Experiment!D14+50)*(Experiment!D14-50)+(Experiment!E14^2))/((Experiment!D14+50)^2+(Experiment!E14^2)) -> 0.89742771 | S14: =((Experiment!D14+50)*Experiment!E14-Experiment!E14*(Experiment!D14-50))/((Experiment!D14+50)^2+(Experiment!E14^2)) -> -0.0053642508 | T14: =IMSUM(R14,IMPRODUCT(S14,$S$1)) -> 0.897427706755917-0.00536425084868388i | U14: =SQRT(R14^2+S14^2) -> 0.89744374 | V14: =-20*LOG(ABS(U14)) -> 0.93985536 | Y14: =Experiment!#REF! -> #REF! | Z14: =((Experiment!#REF!+50)*(Experiment!#REF!-50)+(Experiment!#REF!^2))/((Experiment!#REF!+50)^2+(Experiment!#REF!^2)) -> #REF! | AA14: =((Experiment!#REF!+50)*Experiment!#REF!-Experiment!#REF!*(Experiment!#REF!-50))/((Experiment!#REF!+50)^2+(Experiment!#REF!^2)) -> #REF! | AB14: =IMSUM(Z14,IMPRODUCT(AA14,$AA$1)) -> #REF! | AC14: =SQRT(Z14^2+AA14^2) -> #REF! | AD14: =-20*LOG(ABS(AC14)) -> #REF!
... A202: =Experiment!#REF! -> #REF! | B202: =((Experiment!#REF!+50)*(Experiment!#REF!-50)+(Experiment!#REF!^2))/((Experiment!#REF!+50)^2+(Experiment!#REF!^2)) -> #REF! | C202: =((Experiment!#REF!+50)*Experiment!#REF!-Experiment!#REF!*(Experiment!#REF!-50))/((Experiment!#REF!+50)^2+(Experiment!#REF!^2)) -> #REF! | D202: =IMSUM(B202,IMPRODUCT(C202,$C$1)) -> #REF! | E202: =SQRT(B202^2+C202^2) -> #REF! | F202: =-20*LOG(ABS(E202)) -> #REF! | I202: =Experiment!#REF! -> #REF! | J202: =((Experiment!#REF!+50)*(Experiment!#REF!-50)+(Experiment!#REF!^2))/((Experiment!#REF!+50)^2+(Experiment!#REF!^2)) -> #REF! | K202: =((Experiment!#REF!+50)*Experiment!#REF!-Experiment!#REF!*(Experiment!#REF!-50))/((Experiment!#REF!+50)^2+(Experiment!#REF!^2)) -> #REF! | L202: =IMSUM(J202,IMPRODUCT(K202,$K$1)) -> #REF! | M202: =SQRT(J202^2+K202^2) -> #REF! | N202: =-20*LOG(ABS(M202)) -> #REF! | Q202: =Experiment!A202 -> 3000000000 | R202: =((Experiment!D202+50)*(Experiment!D202-50)+(Experiment!E202^2))/((Experiment!D202+50)^2+(Experiment!E202^2)) -> 0.6086674 | S202: =((Experiment!D202+50)*Experiment!E202-Experiment!E202*(Experiment!D202-50))/((Experiment!D202+50)^2+(Experiment!E202^2)) -> -0.71840844 | T202: =IMSUM(R202,IMPRODUCT(S202,$S$1)) -> 0.608667404326443-0.718408443305387i | U202: =SQRT(R202^2+S202^2) -> 0.94158733 | V202: =-20*LOG(ABS(U202)) -> 0.52278788 | Y202: =Experiment!#REF! -> #REF! | Z202: =((Experiment!#REF!+50)*(Experiment!#REF!-50)+(Experiment!#REF!^2))/((Experiment!#REF!+50)^2+(Experiment!#REF!^2)) -> #REF! | AA202: =((Experiment!#REF!+50)*Experiment!#REF!-Experiment!#REF!*(Experiment!#REF!-50))/((Experiment!#REF!+50)^2+(Experiment!#REF!^2)) -> #REF! | AB202: =IMSUM(Z202,IMPRODUCT(AA202,$AA$1)) -> #REF! | AC202: =SQRT(Z202^2+AA202^2) -> #REF! | AD202: =-20*LOG(ABS(AC202)) -> #REF!

Sheet Permitivity
A1: 0.1 | B1: =Experiment!#REF! -> #REF! | C1: 25 | D1: =5.77-0.0274*C1 -> 5.085 | E1: =(10^(1.94404-C1*0.001991))*(1-0.0003742*C1*A1+0.034*(A1^2)-0.178*A1+C1*0.0001515-0.000004929*(C1^2)) -> 77.004157 | F1: =(0.000000000000003745*(1+(0.00007)*(C1-27.5)^2)*EXP(2295.7/(C1+273.15)))*(1.012-C1*A1*0.005282+0.032*(A1^2)-0.01*A1-C1*0.001724+0.00003766*(C1^2)) -> 8.094934e-12 | G1: =-0.0006348*C1*A1-0.051*(A1^2)+0.09*A1 -> 0.006903 | H1: =0.174*C1*A1-1.582*(A1^2)+5.923*A1 -> 1.01148 | I1: Unit | J1: 0+1i | L1: =Reflection!I1 -> #REF! | M1: Unit | N1: 0+1i | T1: 0.011 | U1: =Reflection!Q1 -> NaCl 0.01mol/L | V1: 25 | W1: =5.77-0.0274*V1 -> 5.085 | X1: =(10^(1.94404-V1*0.001991))*(1-0.0003742*V1*T1+0.034*(T1^2)-0.178*T1+V1*0.0001515-0.000004929*(V1^2)) -> 78.284962 | Y1: =(0.000000000000003745*(1+(0.00007)*(V1-27.5)^2)*EXP(2295.7/(V1+273.15)))*(1.012-V1*T1*0.005282+0.032*(T1^2)-0.01*T1-V1*0.001724+0.00003766*(V1^2)) -> 8.1969017e-12 | Z1: =-0.0006348*V1*T1-0.051*(T1^2)+0.09*T1 -> 0.000809259 | AA1: =0.174*V1*T1-1.582*(T1^2)+5.923*T1 -> 0.11281158 | AB1: Unit | AC1: 0+1i | AE1: =Reflection!Y1 -> #REF! | AF1: Unit | AG1: 0+1i
B2: Frequency[Hz] | D2: conductivity | E2: permittivity RE | F2: permittivity IM | G2: conductivity RE | H2: conductivity IM | L2: Frequency[Hz] | M2: permittivity | N2: conductivity | O2: permittivity RE | P2: permittivity IM | Q2: conductivity RE | R2: conductivity IM | U2: Frequency[Hz] | W2: conductivity | X2: permittivity RE | Y2: permittivity IM | Z2: conductivity RE | AA2: conductivity IM | AE2: Frequency[Hz] | AF2: E | AG2: permittivity | AH2: conductivity | AI2: permittivity RE | AJ2: permittivity IM | AK2: conductivity RE | AL2: conductivity IM
B3: =Experiment!#REF! -> #REF! | C3: =IMSUM($D$1,IMDIV(($E$1-$D$1),IMSUM(IMPOWER(IMPRODUCT($J$1,2*PI()*B3*$F$1),(1-$G$1)),1)),IMDIV($H$1,IMPRODUCT($J$1,2*PI()*B3*0.000000000008854))) -> #REF! | D3: =IMPRODUCT(C3,$J$1,2*PI()*B3*0.0000000000088542) -> #REF! | E3: =IMREAL(C3) -> #REF! | F3: =-IMAGINARY(C3) -> #REF! | G3: =IMREAL(D3) -> #REF! | H3: =IMAGINARY(D3) -> #REF! | L3: =Reflection!I3 -> #REF! | M3: =IMSUM(2.6,IMDIV(19.94,IMSUM(1,IMPOWER(IMPRODUCT($N$1,2*PI()*L3,0.0000000001649),1))),IMDIV(0.74,IMSUM(1,IMPRODUCT($N$1,2*PI()*L3*0.0000000000104))),IMDIV(1.19,IMSUM(1,IMPRODUCT($N$1,2*PI()*L3*0.00000000000169)))) -> #REF! | N3: =IMPRODUCT(M3,$N$1,2*PI()*L3*0.0000000000088542) -> #REF! | O3: =IMREAL(M3) -> #REF! | P3: =-IMAGINARY(M3) -> #REF! | Q3: =IMREAL(N3) -> #REF! | R3: =IMAGINARY(N3) -> #REF! | U3: =Reflection!Q3 -> 1000000 | V3: =IMSUM($W$1,IMDIV(($X$1-$W$1),IMSUM(IMPOWER(IMPRODUCT($AC$1,2*PI()*U3*$Y$1),(1-$Z$1)),1)),IMDIV($AA$1,IMPRODUCT($AC$1,2*PI()*U3*0.000000000008854))) -> 78.2849565699642-2027.84661440751i | W3: =IMPRODUCT(V3,$N$1,2*PI()*U3*0.0000000000088542) -> 0.112814337679225+0.00435519405804163i | X3: =IMREAL(V3) -> 78.284957 | Y3: =-IMAGINARY(V3) -> 2027.8466 | Z3: =IMREAL(W3) -> 0.11281434 | AA3: =IMAGINARY(W3) -> 0.0043551941 | AE3: =Reflection!Y3 -> #REF! | AF3: =IMDIV(IMPRODUCT(IMSUB(C3,V3),IMSUB(Reflection!AB3,Reflection!D3),IMSUB(Reflection!L3,Reflection!T3)),IMPRODUCT(IMSUB(Permitivity!M3,Permitivity!V3),IMSUB(Reflection!AB3,Reflection!L3),IMSUB(Reflection!D3,Reflection!T3))) -> #REF! | AG3: =IMDIV(IMSUB(C3,IMPRODUCT(AF3,M3)),IMSUB(1,AF3)) -> #REF! | AH3: =IMPRODUCT(IMPRODUCT(AG3,$AG$1),2*PI()*AE3*0.0000000000088542) -> #REF! | AI3: =IMREAL(AG3) -> #REF! | AJ3: =-IMAGINARY(AG3) -> #REF! | AK3: =IMREAL(AH3) -> #REF! | AL3: =IMAGINARY(AH3) -> #REF!
B4: =Experiment!#REF! -> #REF! | C4: =IMSUM($D$1,IMDIV(($E$1-$D$1),IMSUM(IMPOWER(IMPRODUCT($J$1,2*PI()*B4*$F$1),(1-$G$1)),1)),IMDIV($H$1,IMPRODUCT($J$1,2*PI()*B4*0.000000000008854))) -> #REF! | D4: =IMPRODUCT(C4,$J$1,2*PI()*B4*0.0000000000088542) -> #REF! | E4: =IMREAL(C4) -> #REF! | F4: =-IMAGINARY(C4) -> #REF! | G4: =IMREAL(D4) -> #REF! | H4: =IMAGINARY(D4) -> #REF! | L4: =Reflection!I4 -> #REF! | M4: =IMSUM(2.6,IMDIV(19.94,IMSUM(1,IMPOWER(IMPRODUCT($N$1,2*PI()*L4,0.0000000001649),1))),IMDIV(0.74,IMSUM(1,IMPRODUCT($N$1,2*PI()*L4*0.0000000000104))),IMDIV(1.19,IMSUM(1,IMPRODUCT($N$1,2*PI()*L4*0.00000000000169)))) -> #REF! | N4: =IMPRODUCT(M4,$N$1,2*PI()*L4*0.0000000000088542) -> #REF! | O4: =IMREAL(M4) -> #REF! | P4: =-IMAGINARY(M4) -> #REF! | Q4: =IMREAL(N4) -> #REF! | R4: =IMAGINARY(N4) -> #REF! | U4: =Reflection!Q4 -> 1000000 | V4: =IMSUM($W$1,IMDIV(($X$1-$W$1),IMSUM(IMPOWER(IMPRODUCT($AC$1,2*PI()*U4*$Y$1),(1-$Z$1)),1)),IMDIV($AA$1,IMPRODUCT($AC$1,2*PI()*U4*0.000000000008854))) -> 78.2849565699642-2027.84661440751i | W4: =IMPRODUCT(V4,$N$1,2*PI()*U4*0.0000000000088542) -> 0.112814337679225+0.00435519405804163i | X4: =IMREAL(V4) -> 78.284957 | Y4: =-IMAGINARY(V4) -> 2027.8466 | Z4: =IMREAL(W4) -> 0.11281434 | AA4: =IMAGINARY(W4) -> 0.0043551941 | AE4: =Reflection!Y4 -> #REF! | AF4: =IMDIV(IMPRODUCT(IMSUB(C4,V4),IMSUB(Reflection!AB4,Reflection!D4),IMSUB(Reflection!L4,Reflection!T4)),IMPRODUCT(IMSUB(Permitivity!M4,Permitivity!V4),IMSUB(Reflection!AB4,Reflection!L4),IMSUB(Reflection!D4,Reflection!T4))) -> #REF! | AG4: =IMDIV(IMSUB(C4,IMPRODUCT(AF4,M4)),IMSUB(1,AF4)) -> #REF! | AH4: =IMPRODUCT(IMPRODUCT(AG4,$AG$1),2*PI()*AE4*0.0000000000088542) -> #REF! | AI4: =IMREAL(AG4) -> #REF! | AJ4: =-IMAGINARY(AG4) -> #REF! | AK4: =IMREAL(AH4) -> #REF! | AL4: =IMAGINARY(AH4) -> #REF!
B5: =Experiment!#REF! -> #REF! | C5: =IMSUM($D$1,IMDIV(($E$1-$D$1),IMSUM(IMPOWER(IMPRODUCT($J$1,2*PI()*B5*$F$1),(1-$G$1)),1)),IMDIV($H$1,IMPRODUCT($J$1,2*PI()*B5*0.000000000008854))) -> #REF! | D5: =IMPRODUCT(C5,$J$1,2*PI()*B5*0.0000000000088542) -> #REF! | E5: =IMREAL(C5) -> #REF! | F5: =-IMAGINARY(C5) -> #REF! | G5: =IMREAL(D5) -> #REF! | H5: =IMAGINARY(D5) -> #REF! | L5: =Reflection!I5 -> #REF! | M5: =IMSUM(2.6,IMDIV(19.94,IMSUM(1,IMPOWER(IMPRODUCT($N$1,2*PI()*L5,0.0000000001649),1))),IMDIV(0.74,IMSUM(1,IMPRODUCT($N$1,2*PI()*L5*0.0000000000104))),IMDIV(1.19,IMSUM(1,IMPRODUCT($N$1,2*PI()*L5*0.00000000000169)))) -> #REF! | N5: =IMPRODUCT(M5,$N$1,2*PI()*L5*0.0000000000088542) -> #REF! | O5: =IMREAL(M5) -> #REF! | P5: =-IMAGINARY(M5) -> #REF! | Q5: =IMREAL(N5) -> #REF! | R5: =IMAGINARY(N5) -> #REF! | U5: =Reflection!Q5 -> 1100000 | V5: =IMSUM($W$1,IMDIV(($X$1-$W$1),IMSUM(IMPOWER(IMPRODUCT($AC$1,2*PI()*U5*$Y$1),(1-$Z$1)),1)),IMDIV($AA$1,IMPRODUCT($AC$1,2*PI()*U5*0.000000000008854))) -> 78.284956045901-1843.49764736529i | W5: =IMPRODUCT(V5,$N$1,2*PI()*U5*0.0000000000088542) -> 0.112814382057017+0.00479071343177531i | X5: =IMREAL(V5) -> 78.284956 | Y5: =-IMAGINARY(V5) -> 1843.4976 | Z5: =IMREAL(W5) -> 0.11281438 | AA5: =IMAGINARY(W5) -> 0.0047907134 | AE5: =Reflection!Y5 -> #REF! | AF5: =IMDIV(IMPRODUCT(IMSUB(C5,V5),IMSUB(Reflection!AB5,Reflection!D5),IMSUB(Reflection!L5,Reflection!T5)),IMPRODUCT(IMSUB(Permitivity!M5,Permitivity!V5),IMSUB(Reflection!AB5,Reflection!L5),IMSUB(Reflection!D5,Reflection!T5))) -> #REF! | AG5: =IMDIV(IMSUB(C5,IMPRODUCT(AF5,M5)),IMSUB(1,AF5)) -> #REF! | AH5: =IMPRODUCT(IMPRODUCT(AG5,$AG$1),2*PI()*AE5*0.0000000000088542) -> #REF! | AI5: =IMREAL(AG5) -> #REF! | AJ5: =-IMAGINARY(AG5) -> #REF! | AK5: =IMREAL(AH5) -> #REF! | AL5: =IMAGINARY(AH5) -> #REF!
B6: =Experiment!#REF! -> #REF! | C6: =IMSUM($D$1,IMDIV(($E$1-$D$1),IMSUM(IMPOWER(IMPRODUCT($J$1,2*PI()*B6*$F$1),(1-$G$1)),1)),IMDIV($H$1,IMPRODUCT($J$1,2*PI()*B6*0.000000000008854))) -> #REF! | D6: =IMPRODUCT(C6,$J$1,2*PI()*B6*0.0000000000088542) -> #REF! | E6: =IMREAL(C6) -> #REF! | F6: =-IMAGINARY(C6) -> #REF! | G6: =IMREAL(D6) -> #REF! | H6: =IMAGINARY(D6) -> #REF! | L6: =Reflection!I6 -> #REF! | M6: =IMSUM(2.6,IMDIV(19.94,IMSUM(1,IMPOWER(IMPRODUCT($N$1,2*PI()*L6,0.0000000001649),1))),IMDIV(0.74,IMSUM(1,IMPRODUCT($N$1,2*PI()*L6*0.0000000000104))),IMDIV(1.19,IMSUM(1,IMPRODUCT($N$1,2*PI()*L6*0.00000000000169)))) -> #REF! | N6: =IMPRODUCT(M6,$N$1,2*PI()*L6*0.0000000000088542) -> #REF! | O6: =IMREAL(M6) -> #REF! | P6: =-IMAGINARY(M6) -> #REF! | Q6: =IMREAL(N6) -> #REF! | R6: =IMAGINARY(N6) -> #REF! | U6: =Reflection!Q6 -> 1100000 | V6: =IMSUM($W$1,IMDIV(($X$1-$W$1),IMSUM(IMPOWER(IMPRODUCT($AC$1,2*PI()*U6*$Y$1),(1-$Z$1)),1)),IMDIV($AA$1,IMPRODUCT($AC$1,2*PI()*U6*0.000000000008854))) -> 78.284956045901-1843.49764736529i | W6: =IMPRODUCT(V6,$N$1,2*PI()*U6*0.0000000000088542) -> 0.112814382057017+0.00479071343177531i | X6: =IMREAL(V6) -> 78.284956 | Y6: =-IMAGINARY(V6) -> 1843.4976 | Z6: =IMREAL(W6) -> 0.11281438 | AA6: =IMAGINARY(W6) -> 0.0047907134 | AE6: =Reflection!Y6 -> #REF! | AF6: =IMDIV(IMPRODUCT(IMSUB(C6,V6),IMSUB(Reflection!AB6,Reflection!D6),IMSUB(Reflection!L6,Reflection!T6)),IMPRODUCT(IMSUB(Permitivity!M6,Permitivity!V6),IMSUB(Reflection!AB6,Reflection!L6),IMSUB(Reflection!D6,Reflection!T6))) -> #REF! | AG6: =IMDIV(IMSUB(C6,IMPRODUCT(AF6,M6)),IMSUB(1,AF6)) -> #REF! | AH6: =IMPRODUCT(IMPRODUCT(AG6,$AG$1),2*PI()*AE6*0.0000000000088542) -> #REF! | AI6: =IMREAL(AG6) -> #REF! | AJ6: =-IMAGINARY(AG6) -> #REF! | AK6: =IMREAL(AH6) -> #REF! | AL6: =IMAGINARY(AH6) -> #REF!
B7: =Experiment!#REF! -> #REF! | C7: =IMSUM($D$1,IMDIV(($E$1-$D$1),IMSUM(IMPOWER(IMPRODUCT($J$1,2*PI()*B7*$F$1),(1-$G$1)),1)),IMDIV($H$1,IMPRODUCT($J$1,2*PI()*B7*0.000000000008854))) -> #REF! | D7: =IMPRODUCT(C7,$J$1,2*PI()*B7*0.0000000000088542) -> #REF! | E7: =IMREAL(C7) -> #REF! | F7: =-IMAGINARY(C7) -> #REF! | G7: =IMREAL(D7) -> #REF! | H7: =IMAGINARY(D7) -> #REF! | L7: =Reflection!I7 -> #REF! | M7: =IMSUM(2.6,IMDIV(19.94,IMSUM(1,IMPOWER(IMPRODUCT($N$1,2*PI()*L7,0.0000000001649),1))),IMDIV(0.74,IMSUM(1,IMPRODUCT($N$1,2*PI()*L7*0.0000000000104))),IMDIV(1.19,IMSUM(1,IMPRODUCT($N$1,2*PI()*L7*0.00000000000169)))) -> #REF! | N7: =IMPRODUCT(M7,$N$1,2*PI()*L7*0.0000000000088542) -> #REF! | O7: =IMREAL(M7) -> #REF! | P7: =-IMAGINARY(M7) -> #REF! | Q7: =IMREAL(N7) -> #REF! | R7: =IMAGINARY(N7) -> #REF! | U7: =Reflection!Q7 -> 1200000 | V7: =IMSUM($W$1,IMDIV(($X$1-$W$1),IMSUM(IMPOWER(IMPRODUCT($AC$1,2*PI()*U7*$Y$1),(1-$Z$1)),1)),IMDIV($AA$1,IMPRODUCT($AC$1,2*PI()*U7*0.000000000008854))) -> 78.2849555179372-1689.87357141895i | W7: =IMPRODUCT(V7,$N$1,2*PI()*U7*0.0000000000088542) -> 0.11281443065769+0.00522623279941759i | X7: =IMREAL(V7) -> 78.284956 | Y7: =-IMAGINARY(V7) -> 1689.8736 | Z7: =IMREAL(W7) -> 0.11281443 | AA7: =IMAGINARY(W7) -> 0.0052262328 | AE7: =Reflection!Y7 -> #REF! | AF7: =IMDIV(IMPRODUCT(IMSUB(C7,V7),IMSUB(Reflection!AB7,Reflection!D7),IMSUB(Reflection!L7,Reflection!T7)),IMPRODUCT(IMSUB(Permitivity!M7,Permitivity!V7),IMSUB(Reflection!AB7,Reflection!L7),IMSUB(Reflection!D7,Reflection!T7))) -> #REF! | AG7: =IMDIV(IMSUB(C7,IMPRODUCT(AF7,M7)),IMSUB(1,AF7)) -> #REF! | AH7: =IMPRODUCT(IMPRODUCT(AG7,$AG$1),2*PI()*AE7*0.0000000000088542) -> #REF! | AI7: =IMREAL(AG7) -> #REF! | AJ7: =-IMAGINARY(AG7) -> #REF! | AK7: =IMREAL(AH7) -> #REF! | AL7: =IMAGINARY(AH7) -> #REF!
B8: =Experiment!#REF! -> #REF! | C8: =IMSUM($D$1,IMDIV(($E$1-$D$1),IMSUM(IMPOWER(IMPRODUCT($J$1,2*PI()*B8*$F$1),(1-$G$1)),1)),IMDIV($H$1,IMPRODUCT($J$1,2*PI()*B8*0.000000000008854))) -> #REF! | D8: =IMPRODUCT(C8,$J$1,2*PI()*B8*0.0000000000088542) -> #REF! | E8: =IMREAL(C8) -> #REF! | F8: =-IMAGINARY(C8) -> #REF! | G8: =IMREAL(D8) -> #REF! | H8: =IMAGINARY(D8) -> #REF! | L8: =Reflection!I8 -> #REF! | M8: =IMSUM(2.6,IMDIV(19.94,IMSUM(1,IMPOWER(IMPRODUCT($N$1,2*PI()*L8,0.0000000001649),1))),IMDIV(0.74,IMSUM(1,IMPRODUCT($N$1,2*PI()*L8*0.0000000000104))),IMDIV(1.19,IMSUM(1,IMPRODUCT($N$1,2*PI()*L8*0.00000000000169)))) -> #REF! | N8: =IMPRODUCT(M8,$N$1,2*PI()*L8*0.0000000000088542) -> #REF! | O8: =IMREAL(M8) -> #REF! | P8: =-IMAGINARY(M8) -> #REF! | Q8: =IMREAL(N8) -> #REF! | R8: =IMAGINARY(N8) -> #REF! | U8: =Reflection!Q8 -> 1200000 | V8: =IMSUM($W$1,IMDIV(($X$1-$W$1),IMSUM(IMPOWER(IMPRODUCT($AC$1,2*PI()*U8*$Y$1),(1-$Z$1)),1)),IMDIV($AA$1,IMPRODUCT($AC$1,2*PI()*U8*0.000000000008854))) -> 78.2849555179372-1689.87357141895i | W8: =IMPRODUCT(V8,$N$1,2*PI()*U8*0.0000000000088542) -> 0.11281443065769+0.00522623279941759i | X8: =IMREAL(V8) -> 78.284956 | Y8: =-IMAGINARY(V8) -> 1689.8736 | Z8: =IMREAL(W8) -> 0.11281443 | AA8: =IMAGINARY(W8) -> 0.0052262328 | AE8: =Reflection!Y8 -> #REF! | AF8: =IMDIV(IMPRODUCT(IMSUB(C8,V8),IMSUB(Reflection!AB8,Reflection!D8),IMSUB(Reflection!L8,Reflection!T8)),IMPRODUCT(IMSUB(Permitivity!M8,Permitivity!V8),IMSUB(Reflection!AB8,Reflection!L8),IMSUB(Reflection!D8,Reflection!T8))) -> #REF! | AG8: =IMDIV(IMSUB(C8,IMPRODUCT(AF8,M8)),IMSUB(1,AF8)) -> #REF! | AH8: =IMPRODUCT(IMPRODUCT(AG8,$AG$1),2*PI()*AE8*0.0000000000088542) -> #REF! | AI8: =IMREAL(AG8) -> #REF! | AJ8: =-IMAGINARY(AG8) -> #REF! | AK8: =IMREAL(AH8) -> #REF! | AL8: =IMAGINARY(AH8) -> #REF!
B9: =Experiment!#REF! -> #REF! | C9: =IMSUM($D$1,IMDIV(($E$1-$D$1),IMSUM(IMPOWER(IMPRODUCT($J$1,2*PI()*B9*$F$1),(1-$G$1)),1)),IMDIV($H$1,IMPRODUCT($J$1,2*PI()*B9*0.000000000008854))) -> #REF! | D9: =IMPRODUCT(C9,$J$1,2*PI()*B9*0.0000000000088542) -> #REF! | E9: =IMREAL(C9) -> #REF! | F9: =-IMAGINARY(C9) -> #REF! | G9: =IMREAL(D9) -> #REF! | H9: =IMAGINARY(D9) -> #REF! | L9: =Reflection!I9 -> #REF! | M9: =IMSUM(2.6,IMDIV(19.94,IMSUM(1,IMPOWER(IMPRODUCT($N$1,2*PI()*L9,0.0000000001649),1))),IMDIV(0.74,IMSUM(1,IMPRODUCT($N$1,2*PI()*L9*0.0000000000104))),IMDIV(1.19,IMSUM(1,IMPRODUCT($N$1,2*PI()*L9*0.00000000000169)))) -> #REF! | N9: =IMPRODUCT(M9,$N$1,2*PI()*L9*0.0000000000088542) -> #REF! | O9: =IMREAL(M9) -> #REF! | P9: =-IMAGINARY(M9) -> #REF! | Q9: =IMREAL(N9) -> #REF! | R9: =IMAGINARY(N9) -> #REF! | U9: =Reflection!Q9 -> 1300000 | V9: =IMSUM($W$1,IMDIV(($X$1-$W$1),IMSUM(IMPOWER(IMPRODUCT($AC$1,2*PI()*U9*$Y$1),(1-$Z$1)),1)),IMDIV($AA$1,IMPRODUCT($AC$1,2*PI()*U9*0.000000000008854))) -> 78.2849549860712-1559.88402708068i | W9: =IMPRODUCT(V9,$N$1,2*PI()*U9*0.0000000000088542) -> 0.112814483480943+0.00566175216090326i | X9: =IMREAL(V9) -> 78.284955 | Y9: =-IMAGINARY(V9) -> 1559.884 | Z9: =IMREAL(W9) -> 0.11281448 | AA9: =IMAGINARY(W9) -> 0.0056617522 | AE9: =Reflection!Y9 -> #REF! | AF9: =IMDIV(IMPRODUCT(IMSUB(C9,V9),IMSUB(Reflection!AB9,Reflection!D9),IMSUB(Reflection!L9,Reflection!T9)),IMPRODUCT(IMSUB(Permitivity!M9,Permitivity!V9),IMSUB(Reflection!AB9,Reflection!L9),IMSUB(Reflection!D9,Reflection!T9))) -> #REF! | AG9: =IMDIV(IMSUB(C9,IMPRODUCT(AF9,M9)),IMSUB(1,AF9)) -> #REF! | AH9: =IMPRODUCT(IMPRODUCT(AG9,$AG$1),2*PI()*AE9*0.0000000000088542) -> #REF! | AI9: =IMREAL(AG9) -> #REF! | AJ9: =-IMAGINARY(AG9) -> #REF! | AK9: =IMREAL(AH9) -> #REF! | AL9: =IMAGINARY(AH9) -> #REF!
B10: =Experiment!#REF! -> #REF! | C10: =IMSUM($D$1,IMDIV(($E$1-$D$1),IMSUM(IMPOWER(IMPRODUCT($J$1,2*PI()*B10*$F$1),(1-$G$1)),1)),IMDIV($H$1,IMPRODUCT($J$1,2*PI()*B10*0.000000000008854))) -> #REF! | D10: =IMPRODUCT(C10,$J$1,2*PI()*B10*0.0000000000088542) -> #REF! | E10: =IMREAL(C10) -> #REF! | F10: =-IMAGINARY(C10) -> #REF! | G10: =IMREAL(D10) -> #REF! | H10: =IMAGINARY(D10) -> #REF! | L10: =Reflection!I10 -> #REF! | M10: =IMSUM(2.6,IMDIV(19.94,IMSUM(1,IMPOWER(IMPRODUCT($N$1,2*PI()*L10,0.0000000001649),1))),IMDIV(0.74,IMSUM(1,IMPRODUCT($N$1,2*PI()*L10*0.0000000000104))),IMDIV(1.19,IMSUM(1,IMPRODUCT($N$1,2*PI()*L10*0.00000000000169)))) -> #REF! | N10: =IMPRODUCT(M10,$N$1,2*PI()*L10*0.0000000000088542) -> #REF! | O10: =IMREAL(M10) -> #REF! | P10: =-IMAGINARY(M10) -> #REF! | Q10: =IMREAL(N10) -> #REF! | R10: =IMAGINARY(N10) -> #REF! | U10: =Reflection!Q10 -> 1300000 | V10: =IMSUM($W$1,IMDIV(($X$1-$W$1),IMSUM(IMPOWER(IMPRODUCT($AC$1,2*PI()*U10*$Y$1),(1-$Z$1)),1)),IMDIV($AA$1,IMPRODUCT($AC$1,2*PI()*U10*0.000000000008854))) -> 78.2849549860712-1559.88402708068i | W10: =IMPRODUCT(V10,$N$1,2*PI()*U10*0.0000000000088542) -> 0.112814483480943+0.00566175216090326i | X10: =IMREAL(V10) -> 78.284955 | Y10: =-IMAGINARY(V10) -> 1559.884 | Z10: =IMREAL(W10) -> 0.11281448 | AA10: =IMAGINARY(W10) -> 0.0056617522 | AE10: =Reflection!Y10 -> #REF! | AF10: =IMDIV(IMPRODUCT(IMSUB(C10,V10),IMSUB(Reflection!AB10,Reflection!D10),IMSUB(Reflection!L10,Reflection!T10)),IMPRODUCT(IMSUB(Permitivity!M10,Permitivity!V10),IMSUB(Reflection!AB10,Reflection!L10),IMSUB(Reflection!D10,Reflection!T10))) -> #REF! | AG10: =IMDIV(IMSUB(C10,IMPRODUCT(AF10,M10)),IMSUB(1,AF10)) -> #REF! | AH10: =IMPRODUCT(IMPRODUCT(AG10,$AG$1),2*PI()*AE10*0.0000000000088542) -> #REF! | AI10: =IMREAL(AG10) -> #REF! | AJ10: =-IMAGINARY(AG10) -> #REF! | AK10: =IMREAL(AH10) -> #REF! | AL10: =IMAGINARY(AH10) -> #REF!
B11: =Experiment!#REF! -> #REF! | C11: =IMSUM($D$1,IMDIV(($E$1-$D$1),IMSUM(IMPOWER(IMPRODUCT($J$1,2*PI()*B11*$F$1),(1-$G$1)),1)),IMDIV($H$1,IMPRODUCT($J$1,2*PI()*B11*0.000000000008854))) -> #REF! | D11: =IMPRODUCT(C11,$J$1,2*PI()*B11*0.0000000000088542) -> #REF! | E11: =IMREAL(C11) -> #REF! | F11: =-IMAGINARY(C11) -> #REF! | G11: =IMREAL(D11) -> #REF! | H11: =IMAGINARY(D11) -> #REF! | L11: =Reflection!I11 -> #REF! | M11: =IMSUM(2.6,IMDIV(19.94,IMSUM(1,IMPOWER(IMPRODUCT($N$1,2*PI()*L11,0.0000000001649),1))),IMDIV(0.74,IMSUM(1,IMPRODUCT($N$1,2*PI()*L11*0.0000000000104))),IMDIV(1.19,IMSUM(1,IMPRODUCT($N$1,2*PI()*L11*0.00000000000169)))) -> #REF! | N11: =IMPRODUCT(M11,$N$1,2*PI()*L11*0.0000000000088542) -> #REF! | O11: =IMREAL(M11) -> #REF! | P11: =-IMAGINARY(M11) -> #REF! | Q11: =IMREAL(N11) -> #REF! | R11: =IMAGINARY(N11) -> #REF! | U11: =Reflection!Q11 -> 1400000 | V11: =IMSUM($W$1,IMDIV(($X$1-$W$1),IMSUM(IMPOWER(IMPRODUCT($AC$1,2*PI()*U11*$Y$1),(1-$Z$1)),1)),IMDIV($AA$1,IMPRODUCT($AC$1,2*PI()*U11*0.000000000008854))) -> 78.2849544503006-1448.46447185953i | W11: =IMPRODUCT(V11,$N$1,2*PI()*U11*0.0000000000088542) -> 0.112814540526504+0.00609727151616699i | X11: =IMREAL(V11) -> 78.284954 | Y11: =-IMAGINARY(V11) -> 1448.4645 | Z11: =IMREAL(W11) -> 0.11281454 | AA11: =IMAGINARY(W11) -> 0.0060972715 | AE11: =Reflection!Y11 -> #REF! | AF11: =IMDIV(IMPRODUCT(IMSUB(C11,V11),IMSUB(Reflection!AB11,Reflection!D11),IMSUB(Reflection!L11,Reflection!T11)),IMPRODUCT(IMSUB(Permitivity!M11,Permitivity!V11),IMSUB(Reflection!AB11,Reflection!L11),IMSUB(Reflection!D11,Reflection!T11))) -> #REF! | AG11: =IMDIV(IMSUB(C11,IMPRODUCT(AF11,M11)),IMSUB(1,AF11)) -> #REF! | AH11: =IMPRODUCT(IMPRODUCT(AG11,$AG$1),2*PI()*AE11*0.0000000000088542) -> #REF! | AI11: =IMREAL(AG11) -> #REF! | AJ11: =-IMAGINARY(AG11) -> #REF! | AK11: =IMREAL(AH11) -> #REF! | AL11: =IMAGINARY(AH11) -> #REF!
B12: =Experiment!#REF! -> #REF! | C12: =IMSUM($D$1,IMDIV(($E$1-$D$1),IMSUM(IMPOWER(IMPRODUCT($J$1,2*PI()*B12*$F$1),(1-$G$1)),1)),IMDIV($H$1,IMPRODUCT($J$1,2*PI()*B12*0.000000000008854))) -> #REF! | D12: =IMPRODUCT(C12,$J$1,2*PI()*B12*0.0000000000088542) -> #REF! | E12: =IMREAL(C12) -> #REF! | F12: =-IMAGINARY(C12) -> #REF! | G12: =IMREAL(D12) -> #REF! | H12: =IMAGINARY(D12) -> #REF! | L12: =Reflection!I12 -> #REF! | M12: =IMSUM(2.6,IMDIV(19.94,IMSUM(1,IMPOWER(IMPRODUCT($N$1,2*PI()*L12,0.0000000001649),1))),IMDIV(0.74,IMSUM(1,IMPRODUCT($N$1,2*PI()*L12*0.0000000000104))),IMDIV(1.19,IMSUM(1,IMPRODUCT($N$1,2*PI()*L12*0.00000000000169)))) -> #REF! | N12: =IMPRODUCT(M12,$N$1,2*PI()*L12*0.0000000000088542) -> #REF! | O12: =IMREAL(M12) -> #REF! | P12: =-IMAGINARY(M12) -> #REF! | Q12: =IMREAL(N12) -> #REF! | R12: =IMAGINARY(N12) -> #REF! | U12: =Reflection!Q12 -> 1400000 | V12: =IMSUM($W$1,IMDIV(($X$1-$W$1),IMSUM(IMPOWER(IMPRODUCT($AC$1,2*PI()*U12*$Y$1),(1-$Z$1)),1)),IMDIV($AA$1,IMPRODUCT($AC$1,2*PI()*U12*0.000000000008854))) -> 78.2849544503006-1448.46447185953i | W12: =IMPRODUCT(V12,$N$1,2*PI()*U12*0.0000000000088542) -> 0.112814540526504+0.00609727151616699i | X12: =IMREAL(V12) -> 78.284954 | Y12: =-IMAGINARY(V12) -> 1448.4645 | Z12: =IMREAL(W12) -> 0.11281454 | AA12: =IMAGINARY(W12) -> 0.0060972715 | AE12: =Reflection!Y12 -> #REF! | AF12: =IMDIV(IMPRODUCT(IMSUB(C12,V12),IMSUB(Reflection!AB12,Reflection!D12),IMSUB(Reflection!L12,Reflection!T12)),IMPRODUCT(IMSUB(Permitivity!M12,Permitivity!V12),IMSUB(Reflection!AB12,Reflection!L12),IMSUB(Reflection!D12,Reflection!T12))) -> #REF! | AG12: =IMDIV(IMSUB(C12,IMPRODUCT(AF12,M12)),IMSUB(1,AF12)) -> #REF! | AH12: =IMPRODUCT(IMPRODUCT(AG12,$AG$1),2*PI()*AE12*0.0000000000088542) -> #REF! | AI12: =IMREAL(AG12) -> #REF! | AJ12: =-IMAGINARY(AG12) -> #REF! | AK12: =IMREAL(AH12) -> #REF! | AL12: =IMAGINARY(AH12) -> #REF!
B13: =Experiment!#REF! -> #REF! | C13: =IMSUM($D$1,IMDIV(($E$1-$D$1),IMSUM(IMPOWER(IMPRODUCT($J$1,2*PI()*B13*$F$1),(1-$G$1)),1)),IMDIV($H$1,IMPRODUCT($J$1,2*PI()*B13*0.000000000008854))) -> #REF! | D13: =IMPRODUCT(C13,$J$1,2*PI()*B13*0.0000000000088542) -> #REF! | E13: =IMREAL(C13) -> #REF! | F13: =-IMAGINARY(C13) -> #REF! | G13: =IMREAL(D13) -> #REF! | H13: =IMAGINARY(D13) -> #REF! | L13: =Reflection!I13 -> #REF! | M13: =IMSUM(2.6,IMDIV(19.94,IMSUM(1,IMPOWER(IMPRODUCT($N$1,2*PI()*L13,0.0000000001649),1))),IMDIV(0.74,IMSUM(1,IMPRODUCT($N$1,2*PI()*L13*0.0000000000104))),IMDIV(1.19,IMSUM(1,IMPRODUCT($N$1,2*PI()*L13*0.00000000000169)))) -> #REF! | N13: =IMPRODUCT(M13,$N$1,2*PI()*L13*0.0000000000088542) -> #REF! | O13: =IMREAL(M13) -> #REF! | P13: =-IMAGINARY(M13) -> #REF! | Q13: =IMREAL(N13) -> #REF! | R13: =IMAGINARY(N13) -> #REF! | U13: =Reflection!Q13 -> 1500000 | V13: =IMSUM($W$1,IMDIV(($X$1-$W$1),IMSUM(IMPOWER(IMPRODUCT($AC$1,2*PI()*U13*$Y$1),(1-$Z$1)),1)),IMDIV($AA$1,IMPRODUCT($AC$1,2*PI()*U13*0.000000000008854))) -> 78.2849539106245-1351.90090792905i | W13: =IMPRODUCT(V13,$N$1,2*PI()*U13*0.0000000000088542) -> 0.112814601794121+0.00653279086514356i | X13: =IMREAL(V13) -> 78.284954 | Y13: =-IMAGINARY(V13) -> 1351.9009 | Z13: =IMREAL(W13) -> 0.1128146 | AA13: =IMAGINARY(W13) -> 0.0065327909 | AE13: =Reflection!Y13 -> #REF! | AF13: =IMDIV(IMPRODUCT(IMSUB(C13,V13),IMSUB(Reflection!AB13,Reflection!D13),IMSUB(Reflection!L13,Reflection!T13)),IMPRODUCT(IMSUB(Permitivity!M13,Permitivity!V13),IMSUB(Reflection!AB13,Reflection!L13),IMSUB(Reflection!D13,Reflection!T13))) -> #REF! | AG13: =IMDIV(IMSUB(C13,IMPRODUCT(AF13,M13)),IMSUB(1,AF13)) -> #REF! | AH13: =IMPRODUCT(IMPRODUCT(AG13,$AG$1),2*PI()*AE13*0.0000000000088542) -> #REF! | AI13: =IMREAL(AG13) -> #REF! | AJ13: =-IMAGINARY(AG13) -> #REF! | AK13: =IMREAL(AH13) -> #REF! | AL13: =IMAGINARY(AH13) -> #REF!
B14: =Experiment!#REF! -> #REF! | C14: =IMSUM($D$1,IMDIV(($E$1-$D$1),IMSUM(IMPOWER(IMPRODUCT($J$1,2*PI()*B14*$F$1),(1-$G$1)),1)),IMDIV($H$1,IMPRODUCT($J$1,2*PI()*B14*0.000000000008854))) -> #REF! | D14: =IMPRODUCT(C14,$J$1,2*PI()*B14*0.0000000000088542) -> #REF! | E14: =IMREAL(C14) -> #REF! | F14: =-IMAGINARY(C14) -> #REF! | G14: =IMREAL(D14) -> #REF! | H14: =IMAGINARY(D14) -> #REF! | L14: =Reflection!I14 -> #REF! | M14: =IMSUM(2.6,IMDIV(19.94,IMSUM(1,IMPOWER(IMPRODUCT($N$1,2*PI()*L14,0.0000000001649),1))),IMDIV(0.74,IMSUM(1,IMPRODUCT($N$1,2*PI()*L14*0.0000000000104))),IMDIV(1.19,IMSUM(1,IMPRODUCT($N$1,2*PI()*L14*0.00000000000169)))) -> #REF! | N14: =IMPRODUCT(M14,$N$1,2*PI()*L14*0.0000000000088542) -> #REF! | O14: =IMREAL(M14) -> #REF! | P14: =-IMAGINARY(M14) -> #REF! | Q14: =IMREAL(N14) -> #REF! | R14: =IMAGINARY(N14) -> #REF! | U14: =Reflection!Q14 -> 1600000 | V14: =IMSUM($W$1,IMDIV(($X$1-$W$1),IMSUM(IMPOWER(IMPRODUCT($AC$1,2*PI()*U14*$Y$1),(1-$Z$1)),1)),IMDIV($AA$1,IMPRODUCT($AC$1,2*PI()*U14*0.000000000008854))) -> 78.2849533670396-1267.40783691957i | W14: =IMPRODUCT(V14,$N$1,2*PI()*U14*0.0000000000088542) -> 0.112814667283554+0.00696831020776748i | X14: =IMREAL(V14) -> 78.284953 | Y14: =-IMAGINARY(V14) -> 1267.4078 | Z14: =IMREAL(W14) -> 0.11281467 | AA14: =IMAGINARY(W14) -> 0.0069683102 | AE14: =Reflection!Y14 -> #REF! | AF14: =IMDIV(IMPRODUCT(IMSUB(C14,V14),IMSUB(Reflection!AB14,Reflection!D14),IMSUB(Reflection!L14,Reflection!T14)),IMPRODUCT(IMSUB(Permitivity!M14,Permitivity!V14),IMSUB(Reflection!AB14,Reflection!L14),IMSUB(Reflection!D14,Reflection!T14))) -> #REF! | AG14: =IMDIV(IMSUB(C14,IMPRODUCT(AF14,M14)),IMSUB(1,AF14)) -> #REF! | AH14: =IMPRODUCT(IMPRODUCT(AG14,$AG$1),2*PI()*AE14*0.0000000000088542) -> #REF! | AI14: =IMREAL(AG14) -> #REF! | AJ14: =-IMAGINARY(AG14) -> #REF! | AK14: =IMREAL(AH14) -> #REF! | AL14: =IMAGINARY(AH14) -> #REF!
... B202: =Experiment!#REF! -> #REF! | C202: =IMSUM($D$1,IMDIV(($E$1-$D$1),IMSUM(IMPOWER(IMPRODUCT($J$1,2*PI()*B202*$F$1),(1-$G$1)),1)),IMDIV($H$1,IMPRODUCT($J$1,2*PI()*B202*0.000000000008854))) -> #REF! | D202: =IMPRODUCT(C202,$J$1,2*PI()*B202*0.0000000000088542) -> #REF! | E202: =IMREAL(C202) -> #REF! | F202: =-IMAGINARY(C202) -> #REF! | G202: =IMREAL(D202) -> #REF! | H202: =IMAGINARY(D202) -> #REF! | L202: =Reflection!I202 -> #REF! | M202: =IMSUM(2.6,IMDIV(19.94,IMSUM(1,IMPOWER(IMPRODUCT($N$1,2*PI()*L202,0.0000000001649),1))),IMDIV(0.74,IMSUM(1,IMPRODUCT($N$1,2*PI()*L202*0.0000000000104))),IMDIV(1.19,IMSUM(1,IMPRODUCT($N$1,2*PI()*L202*0.00000000000169)))) -> #REF! | N202: =IMPRODUCT(M202,$N$1,2*PI()*L202*0.0000000000088542) -> #REF! | O202: =IMREAL(M202) -> #REF! | P202: =-IMAGINARY(M202) -> #REF! | Q202: =IMREAL(N202) -> #REF! | R202: =IMAGINARY(N202) -> #REF! | U202: =Reflection!Q202 -> 3000000000 | V202: =IMSUM($W$1,IMDIV(($X$1-$W$1),IMSUM(IMPOWER(IMPRODUCT($AC$1,2*PI()*U202*$Y$1),(1-$Z$1)),1)),IMDIV($AA$1,IMPRODUCT($AC$1,2*PI()*U202*0.000000000008854))) -> 76.5597796833092-11.7338882294635i | W202: =IMPRODUCT(V202,$N$1,2*PI()*U202*0.0000000000088542) -> 1.95835940391737+12.7776540540225i | X202: =IMREAL(V202) -> 76.55978 | Y202: =-IMAGINARY(V202) -> 11.733888 | Z202: =IMREAL(W202) -> 1.9583594 | AA202: =IMAGINARY(W202) -> 12.777654 | AE202: =Reflection!Y202 -> #REF! | AF202: =IMDIV(IMPRODUCT(IMSUB(C202,V202),IMSUB(Reflection!AB202,Reflection!D202),IMSUB(Reflection!L202,Reflection!T202)),IMPRODUCT(IMSUB(Permitivity!M202,Permitivity!V202),IMSUB(Reflection!AB202,Reflection!L202),IMSUB(Reflection!D202,Reflection!T202))) -> #REF! | AG202: =IMDIV(IMSUB(C202,IMPRODUCT(AF202,M202)),IMSUB(1,AF202)) -> #REF! | AH202: =IMPRODUCT(IMPRODUCT(AG202,$AG$1),2*PI()*AE202*0.0000000000088542) -> #REF! | AI202: =IMREAL(AG202) -> #REF! | AJ202: =-IMAGINARY(AG202) -> #REF! | AK202: =IMREAL(AH202) -> #REF! | AL202: =IMAGINARY(AH202) -> #REF!

Sheet Permitivity Ref.
A1: Water | B1: Unit | C1: 0+1i | J1: =Reflection!I1 -> #REF! | K1: Unit | L1: 0+1i | S1: Ethanol 0.7 | T1: Unit | U1: 0+1i | AA1: 0.16 | AB1: NaCl | AC1: 25 | AD1: =5.77-0.0274*AC1 -> 5.085 | AE1: =(10^(1.94404-AC1*0.001991))*(1-0.0003742*AC1*AA1+0.034*(AA1^2)-0.178*AA1+AC1*0.0001515-0.000004929*(AC1^2)) -> 76.164522 | AF1: =(0.000000000000003745*(1+(0.00007)*(AC1-27.5)^2)*EXP(2295.7/(AC1+273.15)))*(1.012-AC1*AA1*0.005282+0.032*(AA1^2)-0.01*AA1-AC1*0.001724+0.00003766*(AC1^2)) -> 8.0285583e-12 | AG1: =-0.0006348*AC1*AA1-0.051*(AA1^2)+0.09*AA1 -> 0.0105552 | AH1: =0.174*AC1*AA1-1.582*(AA1^2)+5.923*AA1 -> 1.6031808 | AI1: Unit | AJ1: 0+1i | AK1: NaCl 0.01mol/L | AL1: Unit | AM1: 0+1i
A2: Frequency[Hz] | B2: permittivity | C2: conductivity | D2: permittivity RE | E2: permittivity IM | F2: conductivity RE | G2: conductivity IM | J2: Frequency[Hz] | K2: permittivity | L2: conductivity | M2: permittivity RE | N2: permittivity IM | O2: conductivity RE | P2: conductivity IM | S2: Frequency[Hz] | T2: permittivity | U2: conductivity | V2: permittivity RE | W2: permittivity IM | X2: conductivity RE | Y2: conductivity IM | AB2: Frequency[Hz] | AC2: permittivity | AD2: conductivity | AE2: permittivity RE | AF2: permittivity IM | AG2: conductivity RE | AH2: conductivity IM | AK2: Frequency[Hz] | AL2: permittivity | AM2: conductivity | AN2: permittivity RE | AO2: permittivity IM | AP2: conductivity RE | AQ2: conductivity IM
A3: =Reflection!A3 -> #REF! | B3: =IMSUM(4.1,IMDIV((78.4-4.1),IMSUM(IMPRODUCT($C$1,2*PI()*A3*0.0000000000083),1))) -> #REF! | C3: =IMPRODUCT(IMPRODUCT(B3,$C$1),2*PI()*A3*0.000000000008854) -> #REF! | D3: =IMREAL(B3) -> #REF! | E3: =-IMAGINARY(B3) -> #REF! | F3: =IMREAL(C3) -> #REF! | G3: =IMAGINARY(C3) -> #REF! | J3: =Reflection!A3 -> #REF! | K3: =IMSUM(2.6,IMDIV(19.94,IMSUM(1,IMPOWER(IMPRODUCT($L$1,2*PI()*J3,0.0000000001649),1))),IMDIV(0.74,IMSUM(1,IMPRODUCT($L$1,2*PI()*J3*0.0000000000104))),IMDIV(1.19,IMSUM(1,IMPRODUCT($L$1,2*PI()*J3*0.00000000000169)))) -> #REF! | L3: =IMPRODUCT(IMPRODUCT(K3,$L$1),2*PI()*J3*0.0000000000088542) -> #REF! | M3: =IMREAL(K3) -> #REF! | N3: =-IMAGINARY(K3) -> #REF! | O3: =IMREAL(L3) -> #REF! | P3: =IMAGINARY(L3) -> #REF! | S3: =Reflection!A3 -> #REF! | T3: =IMSUM(2.7,IMDIV(25.93,IMSUM(1,IMPOWER(IMPRODUCT($U$1,2*PI()*S3,0.00000000009441),0.956))),IMDIV(1.44,IMSUM(1,IMPRODUCT($U$1,2*PI()*S3*0.00000000000891))),IMDIV(1.28,IMSUM(1,IMPRODUCT($U$1,2*PI()*S3*0.00000000000139)))) -> #REF! | U3: =IMPRODUCT(IMPRODUCT(T3,$U$1),2*PI()*S3*0.0000000000088542) -> #REF! | V3: =IMREAL(T3) -> #REF! | W3: =-IMAGINARY(T3) -> #REF! | X3: =IMREAL(U3) -> #REF! | Y3: =IMAGINARY(U3) -> #REF! | AB3: =Reflection!A3 -> #REF! | AC3: =IMSUM($AD$1,IMSUM(IMDIV(($AE$1-$AD$1),IMSUM(IMPOWER(IMPRODUCT($AJ$1,2*PI()*AB3*$AF$1),(1-$AG$1)),1)),IMDIV($AH$1,IMPRODUCT($AJ$1,2*PI()*AB3*0.000000000008854)))) -> #REF! | AD3: =IMPRODUCT(IMPRODUCT(AC3,$AJ$1),2*PI()*AB3*0.000000000008854) -> #REF! | AE3: =IMREAL(AC3) -> #REF! | AF3: =-IMAGINARY(AC3) -> #REF! | AG3: =IMREAL(AD3) -> #REF! | AH3: =IMAGINARY(AD3) -> #REF! | AK3: =Reflection!A3 -> #REF! | AL3: =IMSUM(4.1,IMDIV((78.4-4.1),IMSUM(IMPRODUCT($AM$1,2*PI()*AK3*0.0000000000083),1))) -> #REF! | AM3: =IMPRODUCT(IMPRODUCT(AL3,$AM$1),2*PI()*AK3*0.000000000008854) -> #REF! | AN3: =IMREAL(AL3) -> #REF! | AO3: =-IMAGINARY(AL3) -> #REF! | AP3: =IMREAL(AM3) -> #REF! | AQ3: =IMAGINARY(AM3) -> #REF!
A4: =Reflection!A4 -> #REF! | B4: =IMSUM(4.1,IMDIV((78.4-4.1),IMSUM(IMPRODUCT($C$1,2*PI()*A4*0.0000000000083),1))) -> #REF! | C4: =IMPRODUCT(IMPRODUCT(B4,$C$1),2*PI()*A4*0.000000000008854) -> #REF! | D4: =IMREAL(B4) -> #REF! | E4: =-IMAGINARY(B4) -> #REF! | F4: =IMREAL(C4) -> #REF! | G4: =IMAGINARY(C4) -> #REF! | J4: =Reflection!A4 -> #REF! | K4: =IMSUM(2.6,IMDIV(19.94,IMSUM(1,IMPOWER(IMPRODUCT($L$1,2*PI()*J4,0.0000000001649),1))),IMDIV(0.74,IMSUM(1,IMPRODUCT($L$1,2*PI()*J4*0.0000000000104))),IMDIV(1.19,IMSUM(1,IMPRODUCT($L$1,2*PI()*J4*0.00000000000169)))) -> #REF! | L4: =IMPRODUCT(IMPRODUCT(K4,$L$1),2*PI()*J4*0.0000000000088542) -> #REF! | M4: =IMREAL(K4) -> #REF! | N4: =-IMAGINARY(K4) -> #REF! | O4: =IMREAL(L4) -> #REF! | P4: =IMAGINARY(L4) -> #REF! | S4: =Reflection!A4 -> #REF! | T4: =IMSUM(2.7,IMDIV(25.93,IMSUM(1,IMPOWER(IMPRODUCT($U$1,2*PI()*S4,0.00000000009441),0.956))),IMDIV(1.44,IMSUM(1,IMPRODUCT($U$1,2*PI()*S4*0.00000000000891))),IMDIV(1.28,IMSUM(1,IMPRODUCT($U$1,2*PI()*S4*0.00000000000139)))) -> #REF! | U4: =IMPRODUCT(IMPRODUCT(T4,$U$1),2*PI()*S4*0.0000000000088542) -> #REF! | V4: =IMREAL(T4) -> #REF! | W4: =-IMAGINARY(T4) -> #REF! | X4: =IMREAL(U4) -> #REF! | Y4: =IMAGINARY(U4) -> #REF! | AB4: =Reflection!A4 -> #REF! | AC4: =IMSUM($AD$1,IMSUM(IMDIV(($AE$1-$AD$1),IMSUM(IMPOWER(IMPRODUCT($AJ$1,2*PI()*AB4*$AF$1),(1-$AG$1)),1)),IMDIV($AH$1,IMPRODUCT($AJ$1,2*PI()*AB4*0.000000000008854)))) -> #REF! | AD4: =IMPRODUCT(IMPRODUCT(AC4,$AJ$1),2*PI()*AB4*0.000000000008854) -> #REF! | AE4: =IMREAL(AC4) -> #REF! | AF4: =-IMAGINARY(AC4) -> #REF! | AG4: =IMREAL(AD4) -> #REF! | AH4: =IMAGINARY(AD4) -> #REF! | AK4: =Reflection!A4 -> #REF! | AL4: =IMSUM(4.1,IMDIV((78.4-4.1),IMSUM(IMPRODUCT($AM$1,2*PI()*AK4*0.0000000000083),1))) -> #REF! | AM4: =IMPRODUCT(IMPRODUCT(AL4,$AM$1),2*PI()*AK4*0.000000000008854) -> #REF! | AN4: =IMREAL(AL4) -> #REF! | AO4: =-IMAGINARY(AL4) -> #REF! | AP4: =IMREAL(AM4) -> #REF! | AQ4: =IMAGINARY(AM4) -> #REF!
A5: =Reflection!A5 -> #REF! | B5: =IMSUM(4.1,IMDIV((78.4-4.1),IMSUM(IMPRODUCT($C$1,2*PI()*A5*0.0000000000083),1))) -> #REF! | C5: =IMPRODUCT(IMPRODUCT(B5,$C$1),2*PI()*A5*0.000000000008854) -> #REF! | D5: =IMREAL(B5) -> #REF! | E5: =-IMAGINARY(B5) -> #REF! | F5: =IMREAL(C5) -> #REF! | G5: =IMAGINARY(C5) -> #REF! | J5: =Reflection!A5 -> #REF! | K5: =IMSUM(2.6,IMDIV(19.94,IMSUM(1,IMPOWER(IMPRODUCT($L$1,2*PI()*J5,0.0000000001649),1))),IMDIV(0.74,IMSUM(1,IMPRODUCT($L$1,2*PI()*J5*0.0000000000104))),IMDIV(1.19,IMSUM(1,IMPRODUCT($L$1,2*PI()*J5*0.00000000000169)))) -> #REF! | L5: =IMPRODUCT(IMPRODUCT(K5,$L$1),2*PI()*J5*0.0000000000088542) -> #REF! | M5: =IMREAL(K5) -> #REF! | N5: =-IMAGINARY(K5) -> #REF! | O5: =IMREAL(L5) -> #REF! | P5: =IMAGINARY(L5) -> #REF! | S5: =Reflection!A5 -> #REF! | T5: =IMSUM(2.7,IMDIV(25.93,IMSUM(1,IMPOWER(IMPRODUCT($U$1,2*PI()*S5,0.00000000009441),0.956))),IMDIV(1.44,IMSUM(1,IMPRODUCT($U$1,2*PI()*S5*0.00000000000891))),IMDIV(1.28,IMSUM(1,IMPRODUCT($U$1,2*PI()*S5*0.00000000000139)))) -> #REF! | U5: =IMPRODUCT(IMPRODUCT(T5,$U$1),2*PI()*S5*0.0000000000088542) -> #REF! | V5: =IMREAL(T5) -> #REF! | W5: =-IMAGINARY(T5) -> #REF! | X5: =IMREAL(U5) -> #REF! | Y5: =IMAGINARY(U5) -> #REF! | AB5: =Reflection!A5 -> #REF! | AC5: =IMSUM($AD$1,IMSUM(IMDIV(($AE$1-$AD$1),IMSUM(IMPOWER(IMPRODUCT($AJ$1,2*PI()*AB5*$AF$1),(1-$AG$1)),1)),IMDIV($AH$1,IMPRODUCT($AJ$1,2*PI()*AB5*0.000000000008854)))) -> #REF! | AD5: =IMPRODUCT(IMPRODUCT(AC5,$AJ$1),2*PI()*AB5*0.000000000008854) -> #REF! | AE5: =IMREAL(AC5) -> #REF! | AF5: =-IMAGINARY(AC5) -> #REF! | AG5: =IMREAL(AD5) -> #REF! | AH5: =IMAGINARY(AD5) -> #REF! | AK5: =Reflection!A5 -> #REF! | AL5: =IMSUM(4.1,IMDIV((78.4-4.1),IMSUM(IMPRODUCT($AM$1,2*PI()*AK5*0.0000000000083),1))) -> #REF! | AM5: =IMPRODUCT(IMPRODUCT(AL5,$AM$1),2*PI()*AK5*0.000000000008854) -> #REF! | AN5: =IMREAL(AL5) -> #REF! | AO5: =-IMAGINARY(AL5) -> #REF! | AP5: =IMREAL(AM5) -> #REF! | AQ5: =IMAGINARY(AM5) -> #REF!
A6: =Reflection!A6 -> #REF! | B6: =IMSUM(4.1,IMDIV((78.4-4.1),IMSUM(IMPRODUCT($C$1,2*PI()*A6*0.0000000000083),1))) -> #REF! | C6: =IMPRODUCT(IMPRODUCT(B6,$C$1),2*PI()*A6*0.000000000008854) -> #REF! | D6: =IMREAL(B6) -> #REF! | E6: =-IMAGINARY(B6) -> #REF! | F6: =IMREAL(C6) -> #REF! | G6: =IMAGINARY(C6) -> #REF! | J6: =Reflection!A6 -> #REF! | K6: =IMSUM(2.6,IMDIV(19.94,IMSUM(1,IMPOWER(IMPRODUCT($L$1,2*PI()*J6,0.0000000001649),1))),IMDIV(0.74,IMSUM(1,IMPRODUCT($L$1,2*PI()*J6*0.0000000000104))),IMDIV(1.19,IMSUM(1,IMPRODUCT($L$1,2*PI()*J6*0.00000000000169)))) -> #REF! | L6: =IMPRODUCT(IMPRODUCT(K6,$L$1),2*PI()*J6*0.0000000000088542) -> #REF! | M6: =IMREAL(K6) -> #REF! | N6: =-IMAGINARY(K6) -> #REF! | O6: =IMREAL(L6) -> #REF! | P6: =IMAGINARY(L6) -> #REF! | S6: =Reflection!A6 -> #REF! | T6: =IMSUM(2.7,IMDIV(25.93,IMSUM(1,IMPOWER(IMPRODUCT($U$1,2*PI()*S6,0.00000000009441),0.956))),IMDIV(1.44,IMSUM(1,IMPRODUCT($U$1,2*PI()*S6*0.00000000000891))),IMDIV(1.28,IMSUM(1,IMPRODUCT($U$1,2*PI()*S6*0.00000000000139)))) -> #REF! | U6: =IMPRODUCT(IMPRODUCT(T6,$U$1),2*PI()*S6*0.0000000000088542) -> #REF! | V6: =IMREAL(T6) -> #REF! | W6: =-IMAGINARY(T6) -> #REF! | X6: =IMREAL(U6) -> #REF! | Y6: =IMAGINARY(U6) -> #REF! | AB6: =Reflection!A6 -> #REF! | AC6: =IMSUM($AD$1,IMSUM(IMDIV(($AE$1-$AD$1),IMSUM(IMPOWER(IMPRODUCT($AJ$1,2*PI()*AB6*$AF$1),(1-$AG$1)),1)),IMDIV($AH$1,IMPRODUCT($AJ$1,2*PI()*AB6*0.000000000008854)))) -> #REF! | AD6: =IMPRODUCT(IMPRODUCT(AC6,$AJ$1),2*PI()*AB6*0.000000000008854) -> #REF! | AE6: =IMREAL(AC6) -> #REF! | AF6: =-IMAGINARY(AC6) -> #REF! | AG6: =IMREAL(AD6) -> #REF! | AH6: =IMAGINARY(AD6) -> #REF! | AK6: =Reflection!A6 -> #REF! | AL6: =IMSUM(4.1,IMDIV((78.4-4.1),IMSUM(IMPRODUCT($AM$1,2*PI()*AK6*0.0000000000083),1))) -> #REF! | AM6: =IMPRODUCT(IMPRODUCT(AL6,$AM$1),2*PI()*AK6*0.000000000008854) -> #REF! | AN6: =IMREAL(AL6) -> #REF! | AO6: =-IMAGINARY(AL6) -> #REF! | AP6: =IMREAL(AM6) -> #REF! | AQ6: =IMAGINARY(AM6) -> #REF!
